[2024-07-03T23:42:28.029+0000] {taskinstance.py:1103} INFO - Dependencies all met for dep_context=non-requeueable deps ti=<TaskInstance: user_generator.generate_data scheduled__2024-07-03T06:00:00+00:00 [queued]>
[2024-07-03T23:42:28.033+0000] {taskinstance.py:1103} INFO - Dependencies all met for dep_context=requeueable deps ti=<TaskInstance: user_generator.generate_data scheduled__2024-07-03T06:00:00+00:00 [queued]>
[2024-07-03T23:42:28.033+0000] {taskinstance.py:1308} INFO - Starting attempt 1 of 2
[2024-07-03T23:42:28.037+0000] {taskinstance.py:1327} INFO - Executing <Task(PythonOperator): generate_data> on 2024-07-03 06:00:00+00:00
[2024-07-03T23:42:28.039+0000] {standard_task_runner.py:57} INFO - Started process 540 to run task
[2024-07-03T23:42:28.040+0000] {standard_task_runner.py:84} INFO - Running: ['airflow', 'tasks', 'run', 'user_generator', 'generate_data', 'scheduled__2024-07-03T06:00:00+00:00', '--job-id', '537', '--raw', '--subdir', 'DAGS_FOLDER/user_generator_dag.py', '--cfg-path', '/tmp/tmpgmz6au02']
[2024-07-03T23:42:28.041+0000] {standard_task_runner.py:85} INFO - Job 537: Subtask generate_data
[2024-07-03T23:42:28.062+0000] {task_command.py:410} INFO - Running <TaskInstance: user_generator.generate_data scheduled__2024-07-03T06:00:00+00:00 [running]> on host a4053733dbc4
[2024-07-03T23:42:28.100+0000] {taskinstance.py:1545} INFO - Exporting env vars: AIRFLOW_CTX_DAG_OWNER='airflow' AIRFLOW_CTX_DAG_ID='user_generator' AIRFLOW_CTX_TASK_ID='generate_data' AIRFLOW_CTX_EXECUTION_DATE='2024-07-03T06:00:00+00:00' AIRFLOW_CTX_TRY_NUMBER='1' AIRFLOW_CTX_DAG_RUN_ID='scheduled__2024-07-03T06:00:00+00:00'
[2024-07-03T23:42:28.100+0000] {logging_mixin.py:149} INFO - Running data generation script...
[2024-07-03T23:42:28.161+0000] {logging_mixin.py:149} INFO - Error in generate_data: Command '['python3', '/opt/airflow/generator/user_generator.py']' returned non-zero exit status 2.
[2024-07-03T23:42:28.161+0000] {logging_mixin.py:149} INFO - stdout: 
[2024-07-03T23:42:28.161+0000] {logging_mixin.py:149} INFO - stderr: python3: can't open file '/opt/airflow/generator/user_generator.py': [Errno 2] No such file or directory
[2024-07-03T23:42:28.161+0000] {python.py:183} INFO - Done. Returned value was: None
[2024-07-03T23:42:28.167+0000] {taskinstance.py:1345} INFO - Marking task as SUCCESS. dag_id=user_generator, task_id=generate_data, execution_date=20240703T060000, start_date=20240703T234228, end_date=20240703T234228
[2024-07-03T23:42:28.183+0000] {local_task_job_runner.py:225} INFO - Task exited with return code 0
[2024-07-03T23:42:28.195+0000] {taskinstance.py:2651} INFO - 0 downstream tasks scheduled from follow-on schedule check
