[2024-07-04T02:39:22.568+0000] {taskinstance.py:1103} INFO - Dependencies all met for dep_context=non-requeueable deps ti=<TaskInstance: dbt_run_dag.run_dbt manual__2024-07-04T02:16:03.677533+00:00 [queued]>
[2024-07-04T02:39:22.571+0000] {taskinstance.py:1103} INFO - Dependencies all met for dep_context=requeueable deps ti=<TaskInstance: dbt_run_dag.run_dbt manual__2024-07-04T02:16:03.677533+00:00 [queued]>
[2024-07-04T02:39:22.571+0000] {taskinstance.py:1308} INFO - Starting attempt 8 of 8
[2024-07-04T02:39:22.575+0000] {taskinstance.py:1327} INFO - Executing <Task(BashOperator): run_dbt> on 2024-07-04 02:16:03.677533+00:00
[2024-07-04T02:39:22.577+0000] {standard_task_runner.py:57} INFO - Started process 60 to run task
[2024-07-04T02:39:22.578+0000] {standard_task_runner.py:84} INFO - Running: ['airflow', 'tasks', 'run', 'dbt_run_dag', 'run_dbt', 'manual__2024-07-04T02:16:03.677533+00:00', '--job-id', '744', '--raw', '--subdir', 'DAGS_FOLDER/dbt_run_dag.py', '--cfg-path', '/tmp/tmpokqxa2ja']
[2024-07-04T02:39:22.579+0000] {standard_task_runner.py:85} INFO - Job 744: Subtask run_dbt
[2024-07-04T02:39:22.599+0000] {task_command.py:410} INFO - Running <TaskInstance: dbt_run_dag.run_dbt manual__2024-07-04T02:16:03.677533+00:00 [running]> on host 6585ae4859da
[2024-07-04T02:39:22.633+0000] {taskinstance.py:1545} INFO - Exporting env vars: AIRFLOW_CTX_DAG_OWNER='airflow' AIRFLOW_CTX_DAG_ID='dbt_run_dag' AIRFLOW_CTX_TASK_ID='run_dbt' AIRFLOW_CTX_EXECUTION_DATE='2024-07-04T02:16:03.677533+00:00' AIRFLOW_CTX_TRY_NUMBER='8' AIRFLOW_CTX_DAG_RUN_ID='manual__2024-07-04T02:16:03.677533+00:00'
[2024-07-04T02:39:22.634+0000] {subprocess.py:63} INFO - Tmp dir root location: 
 /tmp
[2024-07-04T02:39:22.634+0000] {subprocess.py:75} INFO - Running command: ['/bin/bash', '-c', 'cd /opt/airflow/dbt && dbt run --profiles-dir /opt/airflow/dbt']
[2024-07-04T02:39:22.636+0000] {subprocess.py:86} INFO - Output:
[2024-07-04T02:39:23.629+0000] {subprocess.py:93} INFO - [0m02:39:23  Running with dbt=1.8.3
[2024-07-04T02:39:23.727+0000] {subprocess.py:93} INFO - [0m02:39:23  Registered adapter: ***=1.8.2
[2024-07-04T02:39:23.891+0000] {subprocess.py:93} INFO - [0m02:39:23  Found 1 model, 1 source, 415 macros
[2024-07-04T02:39:23.892+0000] {subprocess.py:93} INFO - [0m02:39:23
[2024-07-04T02:39:23.936+0000] {subprocess.py:93} INFO - [0m02:39:23  Concurrency: 4 threads (target='dev')
[2024-07-04T02:39:23.937+0000] {subprocess.py:93} INFO - [0m02:39:23
[2024-07-04T02:39:23.941+0000] {subprocess.py:93} INFO - [0m02:39:23  1 of 1 START sql view model public.users ....................................... [RUN]
[2024-07-04T02:39:23.972+0000] {subprocess.py:93} INFO - [0m02:39:23  1 of 1 ERROR creating sql view model public.users .............................. [[31mERROR[0m in 0.03s]
[2024-07-04T02:39:23.977+0000] {subprocess.py:93} INFO - [0m02:39:23
[2024-07-04T02:39:23.977+0000] {subprocess.py:93} INFO - [0m02:39:23  Finished running 1 view model in 0 hours 0 minutes and 0.08 seconds (0.08s).
[2024-07-04T02:39:24.004+0000] {subprocess.py:93} INFO - [0m02:39:24
[2024-07-04T02:39:24.004+0000] {subprocess.py:93} INFO - [0m02:39:24  [31mCompleted with 1 error and 0 warnings:[0m
[2024-07-04T02:39:24.004+0000] {subprocess.py:93} INFO - [0m02:39:24
[2024-07-04T02:39:24.004+0000] {subprocess.py:93} INFO - [0m02:39:24    Database Error in model users (models/users.sql)
[2024-07-04T02:39:24.004+0000] {subprocess.py:93} INFO -   relation "public.users" does not exist
[2024-07-04T02:39:24.005+0000] {subprocess.py:93} INFO -   LINE 13:     "company_dw"."public"."users"
[2024-07-04T02:39:24.005+0000] {subprocess.py:93} INFO -                ^
[2024-07-04T02:39:24.006+0000] {subprocess.py:93} INFO -   compiled Code at target/run/ecomm_data_demo/models/users.sql
[2024-07-04T02:39:24.006+0000] {subprocess.py:93} INFO - [0m02:39:24
[2024-07-04T02:39:24.006+0000] {subprocess.py:93} INFO - [0m02:39:24  Done. PASS=0 WARN=0 ERROR=1 SKIP=0 TOTAL=1
[2024-07-04T02:39:24.547+0000] {subprocess.py:97} INFO - Command exited with return code 1
[2024-07-04T02:39:24.553+0000] {taskinstance.py:1824} ERROR - Task failed with exception
Traceback (most recent call last):
  File "/home/airflow/.local/lib/python3.9/site-packages/airflow/operators/bash.py", line 210, in execute
    raise AirflowException(
airflow.exceptions.AirflowException: Bash command failed. The command returned a non-zero exit code 1.
[2024-07-04T02:39:24.555+0000] {taskinstance.py:1345} INFO - Marking task as FAILED. dag_id=dbt_run_dag, task_id=run_dbt, execution_date=20240704T021603, start_date=20240704T023922, end_date=20240704T023924
[2024-07-04T02:39:24.561+0000] {standard_task_runner.py:104} ERROR - Failed to execute job 744 for task run_dbt (Bash command failed. The command returned a non-zero exit code 1.; 60)
[2024-07-04T02:39:24.570+0000] {local_task_job_runner.py:225} INFO - Task exited with return code 1
[2024-07-04T02:39:24.578+0000] {taskinstance.py:2651} INFO - 0 downstream tasks scheduled from follow-on schedule check
